<?xml version="1.0" ?>
<robot name="dexhandv2_cobot_right" xmlns:xacro="http://www.ros.org/wiki/xacro">

<xacro:include filename="$(find dexhandv2_description)/urdf/materials.xacro" />
<xacro:include filename="$(find dexhandv2_description)/urdf/dexhandv2_cobot_right.trans" />
<xacro:include filename="$(find dexhandv2_description)/urdf/dexhandv2_cobot_right.gazebo" />
<link name="base_link">
  <inertial>
    <origin xyz="2.052703407136187e-15 2.220446049250313e-16 0.007619244404461584" rpy="0 0 0"/>
    <mass value="0.40106984932829953"/>
    <inertia ixx="0.000103" iyy="0.000103" izz="0.000181" ixy="0.0" iyz="0.0" ixz="0.0"/>
  </inertial>
  <visual>
    <origin xyz="0 0 0" rpy="0 0 0"/>
    <geometry>
      <mesh filename="package://dexhandv2_description/meshes/cobot_right/base_link.stl" scale="0.001 0.001 0.001"/>
    </geometry>
    <material name="silver"/>
  </visual>
  <collision>
    <origin xyz="0 0 0" rpy="0 0 0"/>
    <geometry>
      <mesh filename="package://dexhandv2_description/meshes/cobot_right/base_link.stl" scale="0.001 0.001 0.001"/>
    </geometry>
  </collision>
</link>

<link name="Index_Knuckle_1">
  <inertial>
    <origin xyz="-0.005617754616359744 -0.004262893684497563 0.0244593212098696" rpy="0 0 0"/>
    <mass value="0.057232258646826684"/>
    <inertia ixx="1.2e-05" iyy="1.1e-05" izz="2e-06" ixy="-0.0" iyz="-0.0" ixz="0.0"/>
  </inertial>
  <visual>
    <origin xyz="-0.006894 -0.034615 -0.230923" rpy="0 0 0"/>
    <geometry>
      <mesh filename="package://dexhandv2_description/meshes/cobot_right/Index_Knuckle_1.stl" scale="0.001 0.001 0.001"/>
    </geometry>
    <material name="silver"/>
  </visual>
  <collision>
    <origin xyz="-0.006894 -0.034615 -0.230923" rpy="0 0 0"/>
    <geometry>
      <mesh filename="package://dexhandv2_description/meshes/cobot_right/Index_Knuckle_1.stl" scale="0.001 0.001 0.001"/>
    </geometry>
  </collision>
</link>

<link name="Middle_Knuckle_1">
  <inertial>
    <origin xyz="-0.0053425374507652095 -0.004751344962067258 0.024431575198405636" rpy="0 0 0"/>
    <mass value="0.057232258646826684"/>
    <inertia ixx="1.2e-05" iyy="1.1e-05" izz="2e-06" ixy="0.0" iyz="0.0" ixz="0.0"/>
  </inertial>
  <visual>
    <origin xyz="-0.005646 -0.012104 -0.236978" rpy="0 0 0"/>
    <geometry>
      <mesh filename="package://dexhandv2_description/meshes/cobot_right/Middle_Knuckle_1.stl" scale="0.001 0.001 0.001"/>
    </geometry>
    <material name="silver"/>
  </visual>
  <collision>
    <origin xyz="-0.005646 -0.012104 -0.236978" rpy="0 0 0"/>
    <geometry>
      <mesh filename="package://dexhandv2_description/meshes/cobot_right/Middle_Knuckle_1.stl" scale="0.001 0.001 0.001"/>
    </geometry>
  </collision>
</link>

<link name="Ring_Knuckle_1">
  <inertial>
    <origin xyz="-0.004995552898363725 -0.005197955554373898 0.024413907325318923" rpy="0 0 0"/>
    <mass value="0.057232258646826684"/>
    <inertia ixx="1.2e-05" iyy="1.1e-05" izz="2e-06" ixy="0.0" iyz="0.0" ixz="0.0"/>
  </inertial>
  <visual>
    <origin xyz="-0.006759 0.01088 -0.233106" rpy="0 0 0"/>
    <geometry>
      <mesh filename="package://dexhandv2_description/meshes/cobot_right/Ring_Knuckle_1.stl" scale="0.001 0.001 0.001"/>
    </geometry>
    <material name="silver"/>
  </visual>
  <collision>
    <origin xyz="-0.006759 0.01088 -0.233106" rpy="0 0 0"/>
    <geometry>
      <mesh filename="package://dexhandv2_description/meshes/cobot_right/Ring_Knuckle_1.stl" scale="0.001 0.001 0.001"/>
    </geometry>
  </collision>
</link>

<link name="Pinky_Knuckle_1">
  <inertial>
    <origin xyz="-0.0038805527779705827 -0.005627871847661753 0.024520983733089308" rpy="0 0 0"/>
    <mass value="0.057232258646826684"/>
    <inertia ixx="1.2e-05" iyy="1.1e-05" izz="2e-06" ixy="0.0" iyz="0.0" ixz="0.0"/>
  </inertial>
  <visual>
    <origin xyz="-0.009742 0.032368 -0.224778" rpy="0 0 0"/>
    <geometry>
      <mesh filename="package://dexhandv2_description/meshes/cobot_right/Pinky_Knuckle_1.stl" scale="0.001 0.001 0.001"/>
    </geometry>
    <material name="silver"/>
  </visual>
  <collision>
    <origin xyz="-0.009742 0.032368 -0.224778" rpy="0 0 0"/>
    <geometry>
      <mesh filename="package://dexhandv2_description/meshes/cobot_right/Pinky_Knuckle_1.stl" scale="0.001 0.001 0.001"/>
    </geometry>
  </collision>
</link>

<link name="Index_Middle_1">
  <inertial>
    <origin xyz="-0.0013226867506370902 -0.007289091459419767 0.01408557787699416" rpy="0 0 0"/>
    <mass value="0.029055618634630877"/>
    <inertia ixx="2e-06" iyy="2e-06" izz="1e-06" ixy="-0.0" iyz="0.0" ixz="-0.0"/>
  </inertial>
  <visual>
    <origin xyz="-0.003362 -0.037608 -0.275941" rpy="0 0 0"/>
    <geometry>
      <mesh filename="package://dexhandv2_description/meshes/cobot_right/Index_Middle_1.stl" scale="0.001 0.001 0.001"/>
    </geometry>
    <material name="silver"/>
  </visual>
  <collision>
    <origin xyz="-0.003362 -0.037608 -0.275941" rpy="0 0 0"/>
    <geometry>
      <mesh filename="package://dexhandv2_description/meshes/cobot_right/Index_Middle_1.stl" scale="0.001 0.001 0.001"/>
    </geometry>
  </collision>
</link>

<link name="Middle_Middle_1">
  <inertial>
    <origin xyz="-0.0007483887502837826 -0.007382459502653912 0.01407915123683462" rpy="0 0 0"/>
    <mass value="0.029055618634630877"/>
    <inertia ixx="2e-06" iyy="2e-06" izz="1e-06" ixy="0.0" iyz="0.0" ixz="-0.0"/>
  </inertial>
  <visual>
    <origin xyz="-0.001646 -0.014754 -0.281978" rpy="0 0 0"/>
    <geometry>
      <mesh filename="package://dexhandv2_description/meshes/cobot_right/Middle_Middle_1.stl" scale="0.001 0.001 0.001"/>
    </geometry>
    <material name="silver"/>
  </visual>
  <collision>
    <origin xyz="-0.001646 -0.014754 -0.281978" rpy="0 0 0"/>
    <geometry>
      <mesh filename="package://dexhandv2_description/meshes/cobot_right/Middle_Middle_1.stl" scale="0.001 0.001 0.001"/>
    </geometry>
  </collision>
</link>

<link name="Ring_Middle_1">
  <inertial>
    <origin xyz="-0.0001527987693481221 -0.007419438842167106 0.014078367099663536" rpy="0 0 0"/>
    <mass value="0.029055618634630877"/>
    <inertia ixx="2e-06" iyy="2e-06" izz="1e-06" ixy="0.0" iyz="-0.0" ixz="-0.0"/>
  </inertial>
  <visual>
    <origin xyz="-0.002383 0.008588 -0.278091" rpy="0 0 0"/>
    <geometry>
      <mesh filename="package://dexhandv2_description/meshes/cobot_right/Ring_Middle_1.stl" scale="0.001 0.001 0.001"/>
    </geometry>
    <material name="silver"/>
  </visual>
  <collision>
    <origin xyz="-0.002383 0.008588 -0.278091" rpy="0 0 0"/>
    <geometry>
      <mesh filename="package://dexhandv2_description/meshes/cobot_right/Ring_Middle_1.stl" scale="0.001 0.001 0.001"/>
    </geometry>
  </collision>
</link>

<link name="Pinky_Middle_1">
  <inertial>
    <origin xyz="0.0008842937946964939 -0.007397317345788294 0.014062908068738944" rpy="0 0 0"/>
    <mass value="0.029055618634630877"/>
    <inertia ixx="2e-06" iyy="2e-06" izz="1e-06" ixy="0.0" iyz="-0.0" ixz="-0.0"/>
  </inertial>
  <visual>
    <origin xyz="-0.006307 0.030474 -0.269863" rpy="0 0 0"/>
    <geometry>
      <mesh filename="package://dexhandv2_description/meshes/cobot_right/Pinky_Middle_1.stl" scale="0.001 0.001 0.001"/>
    </geometry>
    <material name="silver"/>
  </visual>
  <collision>
    <origin xyz="-0.006307 0.030474 -0.269863" rpy="0 0 0"/>
    <geometry>
      <mesh filename="package://dexhandv2_description/meshes/cobot_right/Pinky_Middle_1.stl" scale="0.001 0.001 0.001"/>
    </geometry>
  </collision>
</link>

<link name="Index_Tip_1">
  <inertial>
    <origin xyz="-0.00031375635025414003 -0.0028004632135323754 0.007068969125634428" rpy="0 0 0"/>
    <mass value="0.018995895295817036"/>
    <inertia ixx="1e-06" iyy="1e-06" izz="0.0" ixy="-0.0" iyz="-0.0" ixz="0.0"/>
  </inertial>
  <visual>
    <origin xyz="-0.003141 -0.033424 -0.305943" rpy="0 0 0"/>
    <geometry>
      <mesh filename="package://dexhandv2_description/meshes/cobot_right/Index_Tip_1.stl" scale="0.001 0.001 0.001"/>
    </geometry>
    <material name="silver"/>
  </visual>
  <collision>
    <origin xyz="-0.003141 -0.033424 -0.305943" rpy="0 0 0"/>
    <geometry>
      <mesh filename="package://dexhandv2_description/meshes/cobot_right/Index_Tip_1.stl" scale="0.001 0.001 0.001"/>
    </geometry>
  </collision>
</link>

<link name="Midle_Tip_1">
  <inertial>
    <origin xyz="-0.00010221029944667464 -0.002819874019605326 0.0070681231302068825" rpy="0 0 0"/>
    <mass value="0.018995895295817036"/>
    <inertia ixx="1e-06" iyy="1e-06" izz="0.0" ixy="0.0" iyz="-0.0" ixz="0.0"/>
  </inertial>
  <visual>
    <origin xyz="-0.001646 -0.010554 -0.311978" rpy="0 0 0"/>
    <geometry>
      <mesh filename="package://dexhandv2_description/meshes/cobot_right/Midle_Tip_1.stl" scale="0.001 0.001 0.001"/>
    </geometry>
    <material name="silver"/>
  </visual>
  <collision>
    <origin xyz="-0.001646 -0.010554 -0.311978" rpy="0 0 0"/>
    <geometry>
      <mesh filename="package://dexhandv2_description/meshes/cobot_right/Midle_Tip_1.stl" scale="0.001 0.001 0.001"/>
    </geometry>
  </collision>
</link>

<link name="Ring_Tip_1">
  <inertial>
    <origin xyz="0.00011843326702077293 -0.002817998278507804 0.007068374926649412" rpy="0 0 0"/>
    <mass value="0.018995895295817036"/>
    <inertia ixx="1e-06" iyy="1e-06" izz="0.0" ixy="0.0" iyz="0.0" ixz="0.0"/>
  </inertial>
  <visual>
    <origin xyz="-0.002642 0.012772 -0.308092" rpy="0 0 0"/>
    <geometry>
      <mesh filename="package://dexhandv2_description/meshes/cobot_right/Ring_Tip_1.stl" scale="0.001 0.001 0.001"/>
    </geometry>
    <material name="silver"/>
  </visual>
  <collision>
    <origin xyz="-0.002642 0.012772 -0.308092" rpy="0 0 0"/>
    <geometry>
      <mesh filename="package://dexhandv2_description/meshes/cobot_right/Ring_Tip_1.stl" scale="0.001 0.001 0.001"/>
    </geometry>
  </collision>
</link>

<link name="Pinky_Tip_1">
  <inertial>
    <origin xyz="0.0005550954751855188 -0.002793293912342454 0.007057169178798339" rpy="0 0 0"/>
    <mass value="0.018995895295817036"/>
    <inertia ixx="1e-06" iyy="1e-06" izz="0.0" ixy="0.0" iyz="0.0" ixz="0.0"/>
  </inertial>
  <visual>
    <origin xyz="-0.007704 0.034606 -0.29984" rpy="0 0 0"/>
    <geometry>
      <mesh filename="package://dexhandv2_description/meshes/cobot_right/Pinky_Tip_1.stl" scale="0.001 0.001 0.001"/>
    </geometry>
    <material name="silver"/>
  </visual>
  <collision>
    <origin xyz="-0.007704 0.034606 -0.29984" rpy="0 0 0"/>
    <geometry>
      <mesh filename="package://dexhandv2_description/meshes/cobot_right/Pinky_Tip_1.stl" scale="0.001 0.001 0.001"/>
    </geometry>
  </collision>
</link>

<link name="Thumb_Prox_KC_1">
  <inertial>
    <origin xyz="-0.005783920817378968 -0.005234416836206375 0.005230066298108099" rpy="0 0 0"/>
    <mass value="0.010139940256668681"/>
    <inertia ixx="0.0" iyy="0.0" izz="0.0" ixy="-0.0" iyz="0.0" ixz="0.0"/>
  </inertial>
  <visual>
    <origin xyz="-0.038353 -0.017798 -0.140638" rpy="0 0 0"/>
    <geometry>
      <mesh filename="package://dexhandv2_description/meshes/cobot_right/Thumb_Prox_KC_1.stl" scale="0.001 0.001 0.001"/>
    </geometry>
    <material name="silver"/>
  </visual>
  <collision>
    <origin xyz="-0.038353 -0.017798 -0.140638" rpy="0 0 0"/>
    <geometry>
      <mesh filename="package://dexhandv2_description/meshes/cobot_right/Thumb_Prox_KC_1.stl" scale="0.001 0.001 0.001"/>
    </geometry>
  </collision>
</link>

<link name="Thumb_Dist_KC_1">
  <inertial>
    <origin xyz="0.007329033205531094 -3.805305769155956e-05 0.005827428222089509" rpy="0 0 0"/>
    <mass value="0.01817352538423656"/>
    <inertia ixx="1e-06" iyy="1e-06" izz="1e-06" ixy="0.0" iyz="-0.0" ixz="-0.0"/>
  </inertial>
  <visual>
    <origin xyz="-0.031128 -0.012 -0.145788" rpy="0 0 0"/>
    <geometry>
      <mesh filename="package://dexhandv2_description/meshes/cobot_right/Thumb_Dist_KC_1.stl" scale="0.001 0.001 0.001"/>
    </geometry>
    <material name="silver"/>
  </visual>
  <collision>
    <origin xyz="-0.031128 -0.012 -0.145788" rpy="0 0 0"/>
    <geometry>
      <mesh filename="package://dexhandv2_description/meshes/cobot_right/Thumb_Dist_KC_1.stl" scale="0.001 0.001 0.001"/>
    </geometry>
  </collision>
</link>

<link name="Thumb_Middle_1">
  <inertial>
    <origin xyz="0.013340753129466254 0.0051575404497526366 0.014104480771110733" rpy="0 0 0"/>
    <mass value="0.042415595330021844"/>
    <inertia ixx="3e-06" iyy="5e-06" izz="4e-06" ixy="0.0" iyz="-0.0" ixz="-1e-06"/>
  </inertial>
  <visual>
    <origin xyz="-0.083225 -0.009293 -0.178216" rpy="0 0 0"/>
    <geometry>
      <mesh filename="package://dexhandv2_description/meshes/cobot_right/Thumb_Middle_1.stl" scale="0.001 0.001 0.001"/>
    </geometry>
    <material name="silver"/>
  </visual>
  <collision>
    <origin xyz="-0.083225 -0.009293 -0.178216" rpy="0 0 0"/>
    <geometry>
      <mesh filename="package://dexhandv2_description/meshes/cobot_right/Thumb_Middle_1.stl" scale="0.001 0.001 0.001"/>
    </geometry>
  </collision>
</link>

<link name="Thumb_Tip_1">
  <inertial>
    <origin xyz="0.007064182715595849 0.00500357358946789 0.009797585836231582" rpy="0 0 0"/>
    <mass value="0.029857587762647974"/>
    <inertia ixx="1e-06" iyy="3e-06" izz="2e-06" ixy="0.0" iyz="-0.0" ixz="-1e-06"/>
  </inertial>
  <visual>
    <origin xyz="-0.114731 -0.009169 -0.202861" rpy="0 0 0"/>
    <geometry>
      <mesh filename="package://dexhandv2_description/meshes/cobot_right/Thumb_Tip_1.stl" scale="0.001 0.001 0.001"/>
    </geometry>
    <material name="silver"/>
  </visual>
  <collision>
    <origin xyz="-0.114731 -0.009169 -0.202861" rpy="0 0 0"/>
    <geometry>
      <mesh filename="package://dexhandv2_description/meshes/cobot_right/Thumb_Tip_1.stl" scale="0.001 0.001 0.001"/>
    </geometry>
  </collision>
</link>

<link name="Index_Knuckle_Cross_1">
  <inertial>
    <origin xyz="-0.008236956200840171 0.0007245443582209743 0.001600789482818915" rpy="0 0 0"/>
    <mass value="0.018067034327727577"/>
    <inertia ixx="1e-06" iyy="1e-06" izz="1e-06" ixy="0.0" iyz="0.0" ixz="-0.0"/>
  </inertial>
  <visual>
    <origin xyz="-0.013926 -0.029177 -0.226889" rpy="0 0 0"/>
    <geometry>
      <mesh filename="package://dexhandv2_description/meshes/cobot_right/Index_Knuckle_Cross_1.stl" scale="0.001 0.001 0.001"/>
    </geometry>
    <material name="silver"/>
  </visual>
  <collision>
    <origin xyz="-0.013926 -0.029177 -0.226889" rpy="0 0 0"/>
    <geometry>
      <mesh filename="package://dexhandv2_description/meshes/cobot_right/Index_Knuckle_Cross_1.stl" scale="0.001 0.001 0.001"/>
    </geometry>
  </collision>
</link>

<link name="Middle_Knuckle_Cross_1">
  <inertial>
    <origin xyz="-0.008276192239981339 2.213623919193261e-07 0.0015609602783075716" rpy="0 0 0"/>
    <mass value="0.018067034327727577"/>
    <inertia ixx="1e-06" iyy="1e-06" izz="1e-06" ixy="0.0" iyz="0.0" ixz="-0.0"/>
  </inertial>
  <visual>
    <origin xyz="-0.013146 -0.007304 -0.232978" rpy="0 0 0"/>
    <geometry>
      <mesh filename="package://dexhandv2_description/meshes/cobot_right/Middle_Knuckle_Cross_1.stl" scale="0.001 0.001 0.001"/>
    </geometry>
    <material name="silver"/>
  </visual>
  <collision>
    <origin xyz="-0.013146 -0.007304 -0.232978" rpy="0 0 0"/>
    <geometry>
      <mesh filename="package://dexhandv2_description/meshes/cobot_right/Middle_Knuckle_Cross_1.stl" scale="0.001 0.001 0.001"/>
    </geometry>
  </collision>
</link>

<link name="Ring_Knuckle_Cross_1">
  <inertial>
    <origin xyz="-0.00825056979269267 -0.0007198415715537147 0.0015306920863781825" rpy="0 0 0"/>
    <mass value="0.018067034327727577"/>
    <inertia ixx="1e-06" iyy="1e-06" izz="1e-06" ixy="-0.0" iyz="-0.0" ixz="-0.0"/>
  </inertial>
  <visual>
    <origin xyz="-0.014663 0.015009 -0.229135" rpy="0 0 0"/>
    <geometry>
      <mesh filename="package://dexhandv2_description/meshes/cobot_right/Ring_Knuckle_Cross_1.stl" scale="0.001 0.001 0.001"/>
    </geometry>
    <material name="silver"/>
  </visual>
  <collision>
    <origin xyz="-0.014663 0.015009 -0.229135" rpy="0 0 0"/>
    <geometry>
      <mesh filename="package://dexhandv2_description/meshes/cobot_right/Ring_Knuckle_Cross_1.stl" scale="0.001 0.001 0.001"/>
    </geometry>
  </collision>
</link>

<link name="Pinky_Knuckle_Cross_1">
  <inertial>
    <origin xyz="-0.008107509458758513 -0.001476079421691763 0.00173636118658535" rpy="0 0 0"/>
    <mass value="0.018067034327727577"/>
    <inertia ixx="1e-06" iyy="1e-06" izz="1e-06" ixy="-0.0" iyz="-0.0" ixz="-0.0"/>
  </inertial>
  <visual>
    <origin xyz="-0.017889 0.035753 -0.220601" rpy="0 0 0"/>
    <geometry>
      <mesh filename="package://dexhandv2_description/meshes/cobot_right/Pinky_Knuckle_Cross_1.stl" scale="0.001 0.001 0.001"/>
    </geometry>
    <material name="silver"/>
  </visual>
  <collision>
    <origin xyz="-0.017889 0.035753 -0.220601" rpy="0 0 0"/>
    <geometry>
      <mesh filename="package://dexhandv2_description/meshes/cobot_right/Pinky_Knuckle_Cross_1.stl" scale="0.001 0.001 0.001"/>
    </geometry>
  </collision>
</link>

<link name="Thumb_Knuckle_1">
  <inertial>
    <origin xyz="0.025838843475506086 -0.005221729505740706 0.0076838729235231" rpy="0 0 0"/>
    <mass value="0.06613687822002302"/>
    <inertia ixx="9e-06" iyy="1.8e-05" izz="1.3e-05" ixy="0.0" iyz="-1e-06" ixz="-7e-06"/>
  </inertial>
  <visual>
    <origin xyz="-0.03637 -0.0201 -0.156921" rpy="0 0 0"/>
    <geometry>
      <mesh filename="package://dexhandv2_description/meshes/cobot_right/Thumb_Knuckle_1.stl" scale="0.001 0.001 0.001"/>
    </geometry>
    <material name="silver"/>
  </visual>
  <collision>
    <origin xyz="-0.03637 -0.0201 -0.156921" rpy="0 0 0"/>
    <geometry>
      <mesh filename="package://dexhandv2_description/meshes/cobot_right/Thumb_Knuckle_1.stl" scale="0.001 0.001 0.001"/>
    </geometry>
  </collision>
</link>

<link name="Solid_Wrist_1">
  <inertial>
    <origin xyz="-0.039506132033453094 -0.009008686051580945 0.1284323760830919" rpy="0 0 0"/>
    <mass value="0.13506264462202147"/>
    <inertia ixx="6.4e-05" iyy="3e-05" izz="4.7e-05" ixy="-0.0" iyz="1e-06" ixz="-2e-06"/>
  </inertial>
  <visual>
    <origin xyz="-0.0322 -0.008656 0.001117" rpy="0 0 0"/>
    <geometry>
      <mesh filename="package://dexhandv2_description/meshes/cobot_right/Solid_Wrist_1.stl" scale="0.001 0.001 0.001"/>
    </geometry>
    <material name="silver"/>
  </visual>
  <collision>
    <origin xyz="-0.0322 -0.008656 0.001117" rpy="0 0 0"/>
    <geometry>
      <mesh filename="package://dexhandv2_description/meshes/cobot_right/Solid_Wrist_1.stl" scale="0.001 0.001 0.001"/>
    </geometry>
  </collision>
</link>

<link name="Palm_1">
  <inertial>
    <origin xyz="0.007689335992022399 0.020098888757707694 0.036007312684782106" rpy="0 0 0"/>
    <mass value="2.5693559159130035"/>
    <inertia ixx="0.003206" iyy="0.001945" izz="0.002103" ixy="4.6e-05" iyz="1.6e-05" ixz="5.9e-05"/>
  </inertial>
  <visual>
    <origin xyz="0.003854 0.021446 -0.141995" rpy="0 0 0"/>
    <geometry>
      <mesh filename="package://dexhandv2_description/meshes/cobot_right/Palm_1.stl" scale="0.001 0.001 0.001"/>
    </geometry>
    <material name="silver"/>
  </visual>
  <collision>
    <origin xyz="0.003854 0.021446 -0.141995" rpy="0 0 0"/>
    <geometry>
      <mesh filename="package://dexhandv2_description/meshes/cobot_right/Palm_1.stl" scale="0.001 0.001 0.001"/>
    </geometry>
  </collision>
</link>

<link name="Cobot_Forearm_1">
  <inertial>
    <origin xyz="-0.001451863595231196 -2.507795103765369e-05 0.04770523191866352" rpy="0 0 0"/>
    <mass value="0.8433305941464591"/>
    <inertia ixx="0.0014" iyy="0.001227" izz="0.00063" ixy="-6e-06" iyz="-2e-06" ixz="2.9e-05"/>
  </inertial>
  <visual>
    <origin xyz="-0.0 -0.0 -0.008" rpy="0 0 0"/>
    <geometry>
      <mesh filename="package://dexhandv2_description/meshes/cobot_right/Cobot_Forearm_1.stl" scale="0.001 0.001 0.001"/>
    </geometry>
    <material name="silver"/>
  </visual>
  <collision>
    <origin xyz="-0.0 -0.0 -0.008" rpy="0 0 0"/>
    <geometry>
      <mesh filename="package://dexhandv2_description/meshes/cobot_right/Cobot_Forearm_1.stl" scale="0.001 0.001 0.001"/>
    </geometry>
  </collision>
</link>

<joint name="R_Index_Pitch" type="revolute">
  <origin xyz="-0.007032 0.005438 0.004034" rpy="0 0 0"/>
  <parent link="Index_Knuckle_Cross_1"/>
  <child link="Index_Knuckle_1"/>
  <axis xyz="0.087537 0.996161 -0.000428"/>
  <limit upper="1.308997" lower="0.0" effort="100" velocity="100"/>
</joint>

<joint name="R_Middle_Pitch" type="revolute">
  <origin xyz="-0.0075 0.0048 0.004" rpy="0 0 0"/>
  <parent link="Middle_Knuckle_Cross_1"/>
  <child link="Middle_Knuckle_1"/>
  <axis xyz="-0.0 1.0 -0.0"/>
  <limit upper="1.308997" lower="0.0" effort="100" velocity="100"/>
</joint>

<joint name="R_Ring_Pitch" type="revolute">
  <origin xyz="-0.007904 0.004129 0.003971" rpy="0 0 0"/>
  <parent link="Ring_Knuckle_Cross_1"/>
  <child link="Ring_Knuckle_1"/>
  <axis xyz="-0.08702 0.996207 -0.00031"/>
  <limit upper="1.308997" lower="0.0" effort="100" velocity="100"/>
</joint>

<joint name="R_Pinky_Pitch" type="revolute">
  <origin xyz="-0.008147 0.003385 0.004177" rpy="0 0 0"/>
  <parent link="Pinky_Knuckle_Cross_1"/>
  <child link="Pinky_Knuckle_1"/>
  <axis xyz="-0.178318 0.983965 0.003854"/>
  <limit upper="1.308997" lower="0.0" effort="100" velocity="100"/>
</joint>

<joint name="R_Index_Flexor" type="revolute">
  <origin xyz="-0.003532 0.002993 0.045018" rpy="0 0 0"/>
  <parent link="Index_Knuckle_1"/>
  <child link="Index_Middle_1"/>
  <axis xyz="0.087537 0.996161 -0.000428"/>
  <limit upper="1.047198" lower="0.0" effort="100" velocity="100"/>
  </joint>

<joint name="R_Middle_Flexor" type="revolute">
  <origin xyz="-0.004 0.00265 0.045" rpy="0 0 0"/>
  <parent link="Middle_Knuckle_1"/>
  <child link="Middle_Middle_1"/>
  <axis xyz="-0.0 1.0 -0.0"/>
  <limit upper="1.047198" lower="0.0" effort="100" velocity="100"/>
</joint>

<joint name="R_Ring_Flexor" type="revolute">
  <origin xyz="-0.004376 0.002292 0.044985" rpy="0 0 0"/>
  <parent link="Ring_Knuckle_1"/>
  <child link="Ring_Middle_1"/>
  <axis xyz="-0.08702 0.996207 -0.00031"/>
  <limit upper="1.047198" lower="0.0" effort="100" velocity="100"/>
</joint>

<joint name="R_Pinky_Flexor" type="revolute">
  <origin xyz="-0.003435 0.001894 0.045085" rpy="0 0 0"/>
  <parent link="Pinky_Knuckle_1"/>
  <child link="Pinky_Middle_1"/>
  <axis xyz="-0.178318 0.983965 0.003854"/>
  <limit upper="1.047198" lower="0.0" effort="100" velocity="100"/>
</joint>

<joint name="R_Index_DIP" type="revolute">
  <origin xyz="-0.000221 -0.004184 0.030002" rpy="0 0 0"/>
  <parent link="Index_Middle_1"/>
  <child link="Index_Tip_1"/>
  <axis xyz="0.087537 0.996161 -0.000428"/>
  <limit upper="1.047198" lower="0.0" effort="100" velocity="100"/>
  <mimic joint="R_Index_Flexor" multiplier="1" offset="0"/>
</joint>

<joint name="R_Middle_DIP" type="revolute">
  <origin xyz="0.0 -0.0042 0.03" rpy="0 0 0"/>
  <parent link="Middle_Middle_1"/>
  <child link="Midle_Tip_1"/>
  <axis xyz="-0.0 1.0 -0.0"/>
  <limit upper="1.047198" lower="0.0" effort="100" velocity="100"/>
  <mimic joint="R_Middle_Flexor" multiplier="1" offset="0"/>
</joint>

<joint name="R_Ring_DIP" type="revolute">
  <origin xyz="0.000259 -0.004184 0.030001" rpy="0 0 0"/>
  <parent link="Ring_Middle_1"/>
  <child link="Ring_Tip_1"/>
  <axis xyz="-0.08702 0.996207 -0.00031"/>
  <limit upper="1.047198" lower="0.0" effort="100" velocity="100"/>
  <mimic joint="R_Ring_Flexor" multiplier="1" offset="0"/>
</joint>

<joint name="R_Pinky_DIP" type="revolute">
  <origin xyz="0.001397 -0.004132 0.029977" rpy="0 0 0"/>
  <parent link="Pinky_Middle_1"/>
  <child link="Pinky_Tip_1"/>
  <axis xyz="-0.178318 0.983965 0.003854"/>
  <limit upper="1.047198" lower="0.0" effort="100" velocity="100"/>
  <mimic joint="R_Pinky_Flexor" multiplier="1" offset="0"/>
</joint>

<joint name="R_Thumb_Yaw" type="revolute">
  <origin xyz="0.042207 0.039244 -0.001357" rpy="0 0 0"/>
  <parent link="Palm_1"/>
  <child link="Thumb_Prox_KC_1"/>
  <axis xyz="0.510615 0.562877 -0.649955"/>
  <limit upper="0.523599" lower="-0.523599" effort="100" velocity="100"/>
</joint>

<joint name="R_Thumb_Roll" type="revolute">
  <origin xyz="-0.007225 -0.005798 0.00515" rpy="0 0 0"/>
  <parent link="Thumb_Prox_KC_1"/>
  <child link="Thumb_Dist_KC_1"/>
  <axis xyz="0.786356 0.0 0.617773"/>
  <limit upper="0.349066" lower="-0.349066" effort="100" velocity="100"/>
</joint>

<joint name="R_Thumb_Flexor" type="revolute">
  <origin xyz="0.046855 -0.010807 0.021295" rpy="0 0 0"/>
  <parent link="Thumb_Knuckle_1"/>
  <child link="Thumb_Middle_1"/>
  <axis xyz="0.34773 -0.826541 -0.442622"/>
  <limit upper="1.047198" lower="0.0" effort="100" velocity="100"/>
</joint>

<joint name="R_Thumb_DIP" type="revolute">
  <origin xyz="0.031506 -0.000124 0.024645" rpy="0 0 0"/>
  <parent link="Thumb_Middle_1"/>
  <child link="Thumb_Tip_1"/>
  <axis xyz="0.34773 -0.826541 -0.442622"/>
  <limit upper="1.047198" lower="0.0" effort="100" velocity="100"/>
  <mimic joint="R_Thumb_Flexor" multiplier="1" offset="0"/>
</joint>

<joint name="R_Index_Yaw" type="revolute">
  <origin xyz="0.01778 0.050623 0.084894" rpy="0 0 0"/>
  <parent link="Palm_1"/>
  <child link="Index_Knuckle_Cross_1"/>
  <axis xyz="0.996149 -0.087538 -0.004875"/>
  <limit upper="0.349066" lower="-0.349066" effort="100" velocity="100"/>
</joint>

<joint name="R_Middle_Yaw" type="revolute">
  <origin xyz="0.017 0.02875 0.090983" rpy="0 0 0"/>
  <parent link="Palm_1"/>
  <child link="Middle_Knuckle_Cross_1"/>
  <axis xyz="1.0 0.0 0.0"/>
  <limit upper="0.349066" lower="-0.349066" effort="100" velocity="100"/>
</joint>

<joint name="R_Ring_Yaw" type="revolute">
  <origin xyz="0.018517 0.006437 0.08714" rpy="0 0 0"/>
  <parent link="Palm_1"/>
  <child link="Ring_Knuckle_Cross_1"/>
  <axis xyz="0.9962 0.08702 0.003551"/>
  <limit upper="0.349066" lower="-0.349066" effort="100" velocity="100"/>
</joint>

<joint name="R_Pinky_Yaw" type="revolute">
  <origin xyz="0.021743 -0.014307 0.078606" rpy="0 0 0"/>
  <parent link="Palm_1"/>
  <child link="Pinky_Knuckle_Cross_1"/>
  <axis xyz="0.983736 0.178359 -0.021263"/>
  <limit upper="0.349066" lower="-0.349066" effort="100" velocity="100"/>
</joint>

<joint name="R_Thumb_Pitch" type="revolute">
  <origin xyz="0.005242 0.0081 0.011133" rpy="0 0 0"/>
  <parent link="Thumb_Dist_KC_1"/>
  <child link="Thumb_Knuckle_1"/>
  <axis xyz="0.34773 -0.826541 -0.442622"/>
  <limit upper="1.047198" lower="0.0" effort="100" velocity="100"/>
</joint>

<joint name="R_Rigid 28" type="fixed">
  <origin xyz="0.0322 0.008656 -0.009117" rpy="0 0 0"/>
  <parent link="Cobot_Forearm_1"/>
  <child link="Solid_Wrist_1"/>
</joint>

<joint name="R_Rigid 30" type="fixed">
  <origin xyz="-0.036054 -0.030102 0.143112" rpy="0 0 0"/>
  <parent link="Solid_Wrist_1"/>
  <child link="Palm_1"/>
</joint>

<joint name="R_Rigid 31" type="fixed">
  <origin xyz="0.0 0.0 0.008" rpy="0 0 0"/>
  <parent link="base_link"/>
  <child link="Cobot_Forearm_1"/>
</joint>

</robot>
